<?xml version="1.0" encoding="utf-8"?>
<!-- This URDF was automatically created by SolidWorks to URDF Exporter! Originally created by Stephen Brawner (brawner@gmail.com) 
     Commit Version: 1.5.1-0-g916b5db  Build Version: 1.5.7152.31018
     For more information, please see http://wiki.ros.org/sw_urdf_exporter -->
<robot
  name="fairino5_v6_robot">
  <link
    name="base_link">
    <inertial>
      <origin
        xyz="-0.00031896 -0.00029673 0.042463"
        rpy="0 0 0" />
      <mass
        value="1.6185" />
      <inertia
        ixx="0.0030836"
        ixy="1.5354E-05"
        ixz="-1.9315E-05"
        iyy="0.0030825"
        iyz="-1.7918E-05"
        izz="0.0045209" />
    </inertial>
    <visual>
      <origin
        xyz="0 0 0"
        rpy="0 0 0" />
      <geometry>
        <mesh
          filename="package://fairino_description/meshes/fairino5_v6/base_link.STL" />
      </geometry>
      <material
        name="">
        <color
          rgba="0.89804 0.91765 0.92941 1" />
      </material>
    </visual>
    <collision>
      <origin
        xyz="0 0 0"
        rpy="0 0 0" />
      <geometry>
        <mesh
          filename="package://fairino_description/meshes/fairino5_v6/base_link.STL" />
      </geometry>
    </collision>
  </link>
  <link
    name="shoulder_link">
    <inertial>
      <origin
        xyz="5.0029E-07 -0.0040922 0.14629"
        rpy="0 0 0" />
      <mass
        value="4.3771" />
      <inertia
        ixx="0.010731"
        ixy="-8.0587E-09"
        ixz="-3.6773E-08"
        iyy="0.010408"
        iyz="0.00012853"
        izz="0.0081793" />
    </inertial>
    <visual>
      <origin
        xyz="0 0 0"
        rpy="0 0 0" />
      <geometry>
        <mesh
          filename="package://fairino_description/meshes/fairino5_v6/shoulder_link.STL" />
      </geometry>
      <material
        name="">
        <color
          rgba="0.89804 0.91765 0.92941 1" />
      </material>
    </visual>
    <collision>
      <origin
        xyz="0 0 0"
        rpy="0 0 0" />
      <geometry>
        <mesh
          filename="package://fairino_description/meshes/fairino5_v6/shoulder_link.STL" />
      </geometry>
    </collision>
  </link>
  <joint
    name="j1"
    type="revolute">
    <origin
      xyz="0 0 0"
      rpy="0 0 0" />
    <parent
      link="base_link" />
    <child
      link="shoulder_link" />
    <axis
      xyz="0 0 1" />
    <limit
      lower="-3.0543"
      upper="3.0543"
      effort="150"
      velocity="3.15" />
    <calibration
      rising="0"
      falling="0" />
    <dynamics
      damping="0"
      friction="0" />
<!--    <safety_controller-->
<!--      soft_lower_limit="-3.0543"-->
<!--      soft_upper_limit="3.0543"-->
<!--      k_position="15"-->
<!--      k_velocity="10" />-->
  </joint>
  <link
    name="upperarm_link">
    <inertial>
      <origin
        xyz="-0.2125 -5.7643E-09 0.1346"
        rpy="0 0 0" />
      <mass
        value="14.458" />
      <inertia
        ixx="0.028392"
        ixy="-1.337E-07"
        ixz="-3.9895E-09"
        iyy="0.4559"
        iyz="4.214E-08"
        izz="0.44974" />
    </inertial>
    <visual>
      <origin
        xyz="0 0 0"
        rpy="0 0 0" />
      <geometry>
        <mesh
          filename="package://fairino_description/meshes/fairino5_v6/upperarm_link.STL" />
      </geometry>
      <material
        name="">
        <color
          rgba="0.89804 0.91765 0.92941 1" />
      </material>
    </visual>
    <collision>
      <origin
        xyz="0 0 0"
        rpy="0 0 0" />
      <geometry>
        <mesh
          filename="package://fairino_description/meshes/fairino5_v6/upperarm_link.STL" />
      </geometry>
    </collision>
  </link>
  <joint
    name="j2"
    type="revolute">
    <origin
      xyz="0 0 0.152"
      rpy="1.5708 0 0" />
    <parent
      link="shoulder_link" />
    <child
      link="upperarm_link" />
    <axis
      xyz="0 0 1" />
    <limit
      lower="-4.6251"
      upper="1.4835"
      effort="150"
      velocity="3.15" />
    <calibration
      rising="0"
      falling="0" />
    <dynamics
      damping="0"
      friction="0" />
<!--    <safety_controller-->
<!--      soft_lower_limit="-4.6251"-->
<!--      soft_upper_limit="1.4835"-->
<!--      k_position="15"-->
<!--      k_velocity="10" />-->
  </joint>
  <link
    name="forearm_link">
    <inertial>
      <origin
        xyz="-0.18793 -8.4503E-07 0.0066357"
        rpy="0 0 0" />
      <mass
        value="7.6737" />
      <inertia
        ixx="0.0085096"
        ixy="2.1613E-06"
        ixz="-0.0068678"
        iyy="0.16971"
        iyz="3.7086E-08"
        izz="0.16854" />
    </inertial>
    <visual>
      <origin
        xyz="0 0 0"
        rpy="0 0 0" />
      <geometry>
        <mesh
          filename="package://fairino_description/meshes/fairino5_v6/forearm_link.STL" />
      </geometry>
      <material
        name="">
        <color
          rgba="0.89804 0.91765 0.92941 1" />
      </material>
    </visual>
    <collision>
      <origin
        xyz="0 0 0"
        rpy="0 0 0" />
      <geometry>
        <mesh
          filename="package://fairino_description/meshes/fairino5_v6/forearm_link.STL" />
      </geometry>
    </collision>
  </link>
  <joint
    name="j3"
    type="revolute">
    <origin
      xyz="-0.425 0 0"
      rpy="0 0 0" />
    <parent
      link="upperarm_link" />
    <child
      link="forearm_link" />
    <axis
      xyz="0 0 1" />
    <limit
      lower="-2.8274"
      upper="2.8274"
      effort="150"
      velocity="3.15" />
    <calibration
      rising="0"
      falling="0" />
    <dynamics
      damping="0"
      friction="0" />
<!--    <safety_controller-->
<!--      soft_lower_limit="-2.8274"-->
<!--      soft_upper_limit="2.8274"-->
<!--      k_position="15"-->
<!--      k_velocity="10" />-->
  </joint>
  <link
    name="wrist1_link">
    <inertial>
      <origin
        xyz="4.98E-07 -0.003754 0.097155"
        rpy="0 0 0" />
      <mass
        value="1.6266" />
      <inertia
        ixx="0.00216"
        ixy="4.888E-09"
        ixz="3.1528E-08"
        iyy="0.0015455"
        iyz="3.7678E-05"
        izz="0.0019902" />
    </inertial>
    <visual>
      <origin
        xyz="0 0 0"
        rpy="0 0 0" />
      <geometry>
        <mesh
          filename="package://fairino_description/meshes/fairino5_v6/wrist1_link.STL" />
      </geometry>
      <material
        name="">
        <color
          rgba="0.89804 0.91765 0.92941 1" />
      </material>
    </visual>
    <collision>
      <origin
        xyz="0 0 0"
        rpy="0 0 0" />
      <geometry>
        <mesh
          filename="package://fairino_description/meshes/fairino5_v6/wrist1_link.STL" />
      </geometry>
    </collision>
  </link>
  <joint
    name="j4"
    type="revolute">
    <origin
      xyz="-0.39501 0 0"
      rpy="0 0 0" />
    <parent
      link="forearm_link" />
    <child
      link="wrist1_link" />
    <axis
      xyz="0 0 1" />
    <limit
      lower="-4.6251"
      upper="1.4835"
      effort="28"
      velocity="3.2" />
    <calibration
      rising="0"
      falling="0" />
    <dynamics
      damping="0"
      friction="0" />
<!--    <safety_controller-->
<!--      soft_lower_limit="-4.6251"-->
<!--      soft_upper_limit="1.4835"-->
<!--      k_position="15"-->
<!--      k_velocity="10" />-->
  </joint>
  <link
    name="wrist2_link">
    <inertial>
      <origin
        xyz="-4.5588E-07 0.0038617 0.098257"
        rpy="0 0 0" />
      <mass
        value="1.5812" />
      <inertia
        ixx="0.0020612"
        ixy="8.7064E-09"
        ixz="-3.4742E-08"
        iyy="0.0014477"
        iyz="-2.8534E-05"
        izz="0.0019573" />
    </inertial>
    <visual>
      <origin
        xyz="0 0 0"
        rpy="0 0 0" />
      <geometry>
        <mesh
          filename="package://fairino_description/meshes/fairino5_v6/wrist2_link.STL" />
      </geometry>
      <material
        name="">
        <color
          rgba="0.89804 0.91765 0.92941 1" />
      </material>
    </visual>
    <collision>
      <origins
        xyz="0 0 0"
        rpy="0 0 0" />
      <geometry>
        <mesh
          filename="package://fairino_description/meshes/fairino5_v6/wrist2_link.STL" />
      </geometry>
    </collision>
  </link>
  <joint
    name="j5"
    type="revolute">
    <origin
      xyz="0 0 0.1021"
      rpy="1.5708 0 0" />
    <parent
      link="wrist1_link" />
    <child
      link="wrist2_link" />
    <axis
      xyz="0 0 1" />
    <limit
      lower="-3.0543"
      upper="3.0543"
      effort="28"
      velocity="3.2" />
    <calibration
      rising="0"
      falling="0" />
    <dynamics
      damping="0"
      friction="0" />
<!--    <safety_controller-->
<!--      soft_lower_limit="-3.0543"-->
<!--      soft_upper_limit="3.0543"-->
<!--      k_position="15"-->
<!--      k_velocity="10" />-->
  </joint>
  <link
    name="wrist3_link">
    <inertial>
      <origin
        xyz="7.7496E-05 1.7751E-05 0.076122"
        rpy="0 0 0" />
      <mass
        value="0.52542" />
      <inertia
        ixx="0.00027721"
        ixy="-1.8677E-09"
        ixz="-1.188E-07"
        iyy="0.00027839"
        iyz="2.2607E-07"
        izz="0.00041605" />
    </inertial>
    <visual>
      <origin
        xyz="0 0 0"
        rpy="0 0 0" />
      <geometry>
        <mesh
          filename="package://fairino_description/meshes/fairino5_v6/wrist3_link.STL" />
      </geometry>
      <material
        name="">
        <color
          rgba="0.89804 0.91765 0.92941 1" />
      </material>
    </visual>
    <collision>
      <origin
        xyz="0 0 0"
        rpy="0 0 0" />
      <geometry>
        <mesh
          filename="package://fairino_description/meshes/fairino5_v6/wrist3_link.STL" />
      </geometry>
    </collision>
  </link>
  <joint
    name="j6"
    type="revolute">
    <origin
      xyz="0 0 0.102"
      rpy="-1.5708 0 0" />
    <parent
      link="wrist2_link" />
    <child
      link="wrist3_link" />
    <axis
      xyz="0 0 1" />
    <limit
      lower="-3.0543"
      upper="3.0543"
      effort="28"
      velocity="3.2" />
    <calibration
      rising="0"
      falling="0" />
    <dynamics
      damping="0"
      friction="0" />
<!--    <safety_controller-->
<!--      soft_lower_limit="-3.0543"-->
<!--      soft_upper_limit="3.0543"-->
<!--      k_position="15"-->
<!--      k_velocity="10" />-->
  </joint>
  <link 
    name="gripper_link1_left">
    <inertial>
      <origin
              xyz="0.00861879642773866 -0.00692892768995967 -0.0138491969037787"
              rpy="0 0 0" />
      <mass
              value="0.011093636660722" />
      <inertia
              ixx="1.08934890488146E-06"
              ixy="9.14784315436547E-07"
              ixz="-2.72327027270803E-07"
              iyy="3.7244617985658E-06"
              iyz="-3.30196602144741E-08"
              izz="4.12126588200292E-06" />
    </inertial>
    <visual>
      <origin
              xyz="0 0 0"
              rpy="0 0 0" />
      <geometry>
        <mesh
                filename="package://fairino_description/meshes/fairino5_v6/gripper_link1_left.STL" />
      </geometry>
      <material
              name="">
        <color
                rgba="1 1 1 1" />
      </material>
    </visual>
    <collision>
      <origin
              xyz="0 0 0"
              rpy="0 0 0" />
      <geometry>
        <mesh
                filename="package://fairino_description/meshes/fairino5_v6/gripper_link1_left.STL" />
      </geometry>
    </collision>
  </link>
  <joint
          name="gripper_joint1_left"
          type="revolute">
    <origin
            xyz="0.025 0.01295 0.1377"
            rpy="-1.5708 0 0" />
    <parent
            link="wrist3_link" />
    <child
            link="gripper_link1_left" />
    <limit
            lower="-1.026"
            upper="0.0"
            effort="0.0"
            velocity="0.0" />
    <axis
            xyz="0 0 1" />
  </joint>
  <link
          name="gripper_link3_left">
    <inertial>
      <origin
              xyz="-0.014334790338123 0.0267713170536268 0.00950100988902113"
              rpy="0 0 0" />
      <mass
              value="0.010606965856657" />
      <inertia
              ixx="2.21321677437824E-06"
              ixy="3.74961617991863E-07"
              ixz="-8.78418529092171E-13"
              iyy="4.64511110876489E-07"
              iyz="3.35600108017678E-12"
              izz="2.12521562895475E-06" />
    </inertial>
    <visual>
      <origin
              xyz="0 0 0"
              rpy="0 0 0" />
      <geometry>
        <mesh
                filename="package://fairino_description/meshes/fairino5_v6/gripper_link3_left.STL" />
      </geometry>
      <material
              name="">
        <color
                rgba="1 1 1 1" />
      </material>
    </visual>
    <collision>
      <origin
              xyz="0 0 0"
              rpy="0 0 0" />
      <geometry>
        <mesh
                filename="package://fairino_description/meshes/fairino5_v6/gripper_link3_left.STL" />
      </geometry>
    </collision>
  </link>
  <joint
          name="gripper_joint3_left"
          type="continuous">
    <origin
            xyz="0.045648 -0.026931 -0.00345"
            rpy="3.1416 0 0" />
    <parent
            link="gripper_link1_left" />
    <child
            link="gripper_link3_left" />
    <axis
            xyz="0 0 1" />
    <mimic
            joint="gripper_joint1_left"
            multiplier="1"
            offset="0" />
  </joint>
  <link
          name="gripper_link2_left">
    <inertial>
      <origin
              xyz="0.0178239345820016 -0.0105147724306264 -0.0127148556432755"
              rpy="0 0 0" />
      <mass
              value="0.00620002211597296" />
      <inertia
              ixx="7.9560070463818E-07"
              ixy="7.00601361842959E-07"
              ixz="-3.75396894165927E-12"
              iyy="1.56948221841704E-06"
              iyz="3.08077226459159E-12"
              izz="1.65589855616728E-06" />
    </inertial>
    <visual>
      <origin
              xyz="0 0 0"
              rpy="0 0 0" />
      <geometry>
        <mesh
                filename="package://fairino_description/meshes/fairino5_v6/gripper_link2_left.STL" />
      </geometry>
      <material
              name="">
        <color
                rgba="1 1 1 1" />
      </material>
    </visual>
    <collision>
      <origin
              xyz="0 0 0"
              rpy="0 0 0" />
      <geometry>
        <mesh
                filename="package://fairino_description/meshes/fairino5_v6/gripper_link2_left.STL" />
      </geometry>
    </collision>
  </link>
  <joint
          name="gripper_joint2_left"
          type="continuous">
    <origin
            xyz="0.0115 0.01295 0.1577"
            rpy="-1.5708 0 0" />
    <parent
            link="wrist3_link" />
    <child
            link="gripper_link2_left" />
    <axis
            xyz="0 0 1" />
    <mimic
            joint="gripper_joint1_left"
            multiplier="1"
            offset="0" />
  </joint>
  <link
          name="gripper_link1_right">
    <inertial>
      <origin
              xyz="-0.0086188 0.0069289 0.011788"
              rpy="0 0 0" />
      <mass
              value="0.011094" />
      <inertia
              ixx="1.0893E-06"
              ixy="9.1478E-07"
              ixz="2.7233E-07"
              iyy="3.7245E-06"
              iyz="3.302E-08"
              izz="4.1213E-06" />
    </inertial>
    <visual>
      <origin
              xyz="0 0 0"
              rpy="0 0 0" />
      <geometry>
        <mesh
                filename="package://fairino_description/meshes/fairino5_v6/gripper_link1_right.STL" />
      </geometry>
      <material
              name="">
        <color
                rgba="1 1 1 1" />
      </material>
    </visual>
    <collision>
      <origin
              xyz="0 0 0"
              rpy="0 0 0" />
      <geometry>
        <mesh
                filename="package://fairino_description/meshes/fairino5_v6/gripper_link1_right.STL" />
      </geometry>
    </collision>
  </link>
  <joint
          name="gripper_joint1_right"
          type="continuous">
    <origin
            xyz="-0.025 0.01295 0.1377"
            rpy="1.5708 0 0" />
    <parent
            link="wrist3_link" />
    <child
            link="gripper_link1_right" />
    <axis
            xyz="0 0 1" />
    <mimic
            joint="gripper_joint1_left"
            multiplier="1"
            offset="0" />
  </joint>
  <link
          name="gripper_link3_right">
    <inertial>
      <origin
              xyz="0.014421 -0.02676 -0.010499"
              rpy="0 0 0" />
      <mass
              value="0.010771" />
      <inertia
              ixx="2.2138E-06"
              ixy="3.7495E-07"
              ixz="8.7931E-13"
              iyy="4.6637E-07"
              iyz="-3.3563E-12"
              izz="2.1271E-06" />
    </inertial>
    <visual>
      <origin
              xyz="0 0 0"
              rpy="0 0 0" />
      <geometry>
        <mesh
                filename="package://fairino_description/meshes/fairino5_v6/gripper_link3_right.STL" />
      </geometry>
      <material
              name="">
        <color
                rgba="1 1 1 1" />
      </material>
    </visual>
    <collision>
      <origin
              xyz="0 0 0"
              rpy="0 0 0" />
      <geometry>
        <mesh
                filename="package://fairino_description/meshes/fairino5_v6/gripper_link3_right.STL" />
      </geometry>
    </collision>
  </link>
  <joint
          name="gripper_joint3_right"
          type="continuous">
    <origin
            xyz="-0.045648 0.026931 0.00245"
            rpy="-3.1416 0 0" />
    <parent
            link="gripper_link1_right" />
    <child
            link="gripper_link3_right" />
    <axis
            xyz="0 0 1" />
    <mimic
            joint="gripper_joint1_left"
            multiplier="1"
            offset="0" />
  </joint>
  <link
          name="gripper_link2_right">
    <inertial>
      <origin
              xyz="-0.017824 0.010515 0.012715"
              rpy="0 0 0" />
      <mass
              value="0.0062" />
      <inertia
              ixx="7.956E-07"
              ixy="7.006E-07"
              ixz="3.754E-12"
              iyy="1.5695E-06"
              iyz="-3.0808E-12"
              izz="1.6559E-06" />
    </inertial>
    <visual>
      <origin
              xyz="0 0 0"
              rpy="0 0 0" />
      <geometry>
        <mesh
                filename="package://fairino_description/meshes/fairino5_v6/gripper_link2_right.STL" />
      </geometry>
      <material
              name="">
        <color
                rgba="1 1 1 1" />
      </material>
    </visual>
    <collision>
      <origin
              xyz="0 0 0"
              rpy="0 0 0" />
      <geometry>
        <mesh
                filename="package://fairino_description/meshes/fairino5_v6/gripper_link2_right.STL" />
      </geometry>
    </collision>
  </link>
  <joint
          name="gripper_joint2_right"
          type="continuous">
    <origin
            xyz="-0.0115 0.01295 0.1577"
            rpy="1.5708 0 0" />
    <parent
            link="wrist3_link" />
    <child
            link="gripper_link2_right" />
    <axis
            xyz="0 0 1" />
    <mimic
            joint="gripper_joint1_left"
            multiplier="1"
            offset="0" />
  </joint>

  <link name="tool_frame" />
  <joint name="tool_joint" type="fixed">
    <origin xyz="0 0 0.22" rpy="0 0 0" />
    <parent link="wrist3_link" />
    <child link="tool_frame" />
  </joint>
</robot>
